<robot
  name="robotiq_arg85_description">

  	<link name="world">
	</link>

	<joint name="arm_joint1" type="prismatic">
		<parent link="world"/>
		<child link="pris_link1"/>
		<origin rpy="0.0 0.0 0.0" xyz="0.0 0.0 0.0"/>
		<axis xyz="1 0 0"/>
		<dynamics damping="10.0" friction="0.0"/>
		<limit lower="-1" upper="1" velocity="500" effort="2000"/>
	</joint>


  	<link name="pris_link1">
		<inertial>
		  <mass value="0.001"/>
		  <inertia ixx="0.1" iyy="0.1" izz="0.1" ixy="0.0" ixz="0.0" iyz="0.0"/>
		</inertial>
	</link>

	<joint name="arm_joint2" type="prismatic">
		<parent link="pris_link1"/>
		<child link="pris_link2"/>
		<origin rpy="0.0 0.0 0.0" xyz="0.0 0.0 0.0"/>
		<axis xyz="0 1 0"/>
		<dynamics damping="10.0" friction="0.0"/>
		<limit lower="-1" upper="1" velocity="500" effort="2000"/>
	</joint>


  	<link name="pris_link2">
		<inertial>
		  <mass value="0.001"/>
		  <inertia ixx="0.1" iyy="0.1" izz="0.1" ixy="0.0" ixz="0.0" iyz="0.0"/>
		</inertial>
	</link>


	<joint name="arm_joint3" type="prismatic">
		<parent link="pris_link2"/>
		<child link="rev_linkx"/>
		<origin rpy="0.0 0.0 0.0" xyz="0.0 0.0 0.0"/>
		<axis xyz="0 0 1"/>
		<dynamics damping="10.0" friction="0.0"/>
		<limit lower="-1" upper="1" velocity="500" effort="2000"/>
	</joint>


  	<link name="rev_linkx">
		<inertial>
		  <mass value="0.001"/>
		  <inertia ixx="0.1" iyy="0.1" izz="0.1" ixy="0.0" ixz="0.0" iyz="0.0"/>
		  <origin rpy="0 0 0" xyz="0.0 0.0 0.0"/>
		</inertial>
	</link>


	<joint name="rev_jointz" type="revolute">
		<axis xyz="0 0 1"/>
		<dynamics damping="10.0" friction="0.0"/>
		<limit effort="2000" lower="-3.14" upper="3.14" velocity="500"/>
		<origin rpy="0 0 0" xyz="0.0 0.0 0.112"/>
		<parent link="rev_linkx"/>
		<child link="rev_linky"/>
	</joint>



  	<link name="rev_linky">
		<inertial>
		  <mass value="0.001"/>
		  <inertia ixx="0.1" iyy="0.1" izz="0.1" ixy="0.0" ixz="0.0" iyz="0.0"/>
		  <origin rpy="0 0 0" xyz="0.0 0.0 0.0"/>

		</inertial>
	</link>


	<joint name="rev_jointy" type="revolute">
		<axis xyz="0 1 0"/>
		<dynamics damping="10.0" friction="0.0"/>
		<limit effort="2000" lower="-3.14" upper="3.14" velocity="500"/>
		<origin rpy="0 0 0" xyz="0.0 0.0 -0.0"/>
		<parent link="rev_linky"/>
		<child link="rev_linkz"/>
	</joint>

  	<link name="rev_linkz">
		<inertial>
		  <mass value="0.001"/>
		  <inertia ixx="0.1" iyy="0.1" izz="0.1" ixy="0.0" ixz="0.0" iyz="0.0"/>
		</inertial>
	</link>


	<joint name="rev_jointx" type="revolute">
		<axis xyz="1 0 0"/>
		<dynamics damping="10.0" friction="0.0"/>
		<limit effort="2000.0" lower="-3.14" upper="3.14" velocity="500"/>
		<origin rpy="0 0 0" xyz="0.0 0.0 -0.0"/>
		<parent link="rev_linkz"/>
		<child link="rev_link_twist"/>
	</joint>


  	<link name="rev_link_twist">
		<inertial>
		  <mass value="0.001"/>
		  <inertia ixx="0.1" iyy="0.1" izz="0.1" ixy="0.0" ixz="0.0" iyz="0.0"/>
		</inertial>
	</link>


	<joint name="rev_twist" type="revolute">
		<axis xyz="0 0 1"/>
		<dynamics damping="10.0" friction="0.0"/>
		<limit effort="2000" lower="-3.14" upper="3.14" velocity="500"/>
		<origin rpy="0 0 0" xyz="0.0 -0.0 0.0"/>
		<parent link="rev_link_twist"/>
		<child link="rev_link1"/>
	</joint>

  	<link name="rev_link1">
		<inertial>
		  <mass value="0.001"/>
		  <inertia ixx="0.1" iyy="0.1" izz="0.1" ixy="0.0" ixz="0.0" iyz="0.0"/>
		  <origin rpy="0 0 0" xyz="0.0 0.0 0.0"/>
		</inertial>
	</link>



	<joint name="rev_joint1" type="revolute">
		<axis xyz="0 0 1"/>
		<dynamics damping="10.0" friction="0.0"/>
		<limit effort="2000" lower="-3.14" upper="3.14" velocity="500"/>
		<origin rpy="0 0 0" xyz="0.0 0.0 -0.112"/>
		<parent link="rev_link1"/>
		<child link="rev_link2"/>
	</joint>

  	<link name="rev_link2">
		<inertial>
		  <mass value="0.001"/>
		  <inertia ixx="0.1" iyy="0.1" izz="0.1" ixy="0.0" ixz="0.0" iyz="0.0"/>
		</inertial>
	</link>


	<joint name="rev_joint2" type="revolute">
		<axis xyz="0 1 0"/>
		<limit effort="2000" lower="-3.14" upper="3.14" velocity="200"/>
		<origin rpy="0 0 0" xyz="0.0 0.0 0.0"/>
		<parent link="rev_link2"/>
		<child link="rev_link3"/>
	</joint>


	<link name="rev_link3">
		<inertial>
		  <mass value="0.001"/>
		  <inertia ixx="0.1" iyy="0.1" izz="0.1" ixy="0.0" ixz="0.0" iyz="0.0"/>
		</inertial>
	</link>

	<joint name="rev_joint3" type="revolute">
		<axis xyz="1 0 0"/>
		<dynamics damping="10.0" friction="0.0"/>
		<limit effort="2000" lower="-3.14" upper="3.14" velocity="200"/>
		<origin rpy="0 0 0" xyz="0.0 0.0 -0.0"/>
		<parent link="rev_link3"/>
		<child link="slide_x"/>
	</joint>

	<link name="slide_x">
		<inertial>
		  <mass value="0.001"/>
		  <inertia ixx="0.1" iyy="0.1" izz="0.1" ixy="0.0" ixz="0.0" iyz="0.0"/>
		</inertial>
	</link>

	<joint name="slide_jointx" type="prismatic">
		<parent link="slide_x"/>
		<child link="slide_y"/>
		<origin rpy="0.0 0.0 0.0" xyz="0.0 0.0 0.0"/>
		<axis xyz="1 0 0"/>
		<dynamics damping="10.0" friction="0.0"/>
		<limit lower="-1" upper="1" velocity="2000" effort="2000"/>
	</joint>


  	<link name="slide_y">
		<inertial>
		  <mass value="0.001"/>
		  <inertia ixx="0.1" iyy="0.1" izz="0.1" ixy="0.0" ixz="0.0" iyz="0.0"/>
		</inertial>
	</link>

	<joint name="slide_jointy" type="prismatic">
		<parent link="slide_y"/>
		<child link="slide_z"/>
		<origin rpy="0.0 0.0 0.0" xyz="0.0 0.0 0.0"/>
		<axis xyz="0 1 0"/>
		<dynamics damping="10.0" friction="0.0"/>
		<limit lower="-1" upper="1" velocity="2000" effort="2000"/>
	</joint>


  	<link name="slide_z">
		<inertial>
		  <mass value="0.001"/>
		  <inertia ixx="0.1" iyy="0.1" izz="0.1" ixy="0.0" ixz="0.0" iyz="0.0"/>
		</inertial>
	</link>


	<joint name="slide_jointz" type="prismatic">
		<parent link="slide_z"/>
		<child link="robotiq_85_base_link"/>
		<origin rpy="0.0 0.0 0.0" xyz="0.0 0.0 0.0"/>
		<axis xyz="0 0 1"/>
		<dynamics damping="10.0" friction="0.0"/>
		<limit lower="-1" upper="1" velocity="2000" effort="2000"/>
	</joint>

  <link name="robotiq_85_base_link">
    <inertial>
      <origin xyz="0.00021987 -2.3546E-10 0.030163" rpy="0 0 0" />
      <mass value="0.30915" />
      <inertia ixx="0.00028972" ixy="-5.7879E-10" ixz="-1.8543E-06"
        iyy="0.00030737" iyz="1.682E-12" izz="0.00019914" />
    </inertial>
    <visual>
      <origin xyz="0 0 0" rpy="-1.57 0 0" />
      <geometry>
        <mesh filename="package://robotiq_arg85_description/meshes/robotiq_85_base_link_fine.STL" />
      </geometry>
      <material name="Dark">
        <color rgba="0.1 0.1 0.1 1" />
      </material>
    </visual>
    <collision>
      <origin xyz="0 0 0" rpy="-1.57 0 0" />
      <geometry>
        <mesh
          filename="package://robotiq_arg85_description/meshes/robotiq_85_base_link_coarse.STL" />
      </geometry>
    </collision>
  </link>
  <link name="left_outer_knuckle">
    <inertial>
      <origin xyz="0.0178331863169983 3.68915177224286E-11 0.0021442477325704" rpy="0 0 0" />
      <mass value="0.00684838849434396" />
      <inertia ixx="2.66832029033166E-07" ixy="1.66142314639824E-15" ixz="1.45945633322873E-07"
        iyy="1.3889233257419E-06" iyz="2.82951161241588E-15" izz="1.26603336914415E-06" />
    </inertial>
    <visual>
      <origin xyz="0 0 0" rpy="0 0 0" />
      <geometry>
        <mesh filename="package://robotiq_arg85_description/meshes/outer_knuckle_fine.STL" />
      </geometry>
      <material name="Light">
        <color rgba="0.792156862745098 0.819607843137255 0.933333333333333 1" />
      </material>
    </visual>
    <collision>
      <origin xyz="0 0 0" rpy="0 0 0" />
      <geometry>
        <mesh filename="package://robotiq_arg85_description/meshes/outer_knuckle_coarse.STL" />
      </geometry>
    </collision>
  </link>
  <joint name="finger_joint" type="revolute">
    <origin xyz="0.0306011 0 0.0627920162695395" rpy="-1.57 0 0" />
    <parent link="robotiq_85_base_link" />
    <child link="left_outer_knuckle" />
    <axis xyz="0 0 -1" />
    <limit lower="0" upper="0.8" velocity="2.0" effort="1000" />
  </joint>
  <link name="left_outer_finger">
    <inertial>
      <origin xyz="0.00131451599174296 2.88942057994543E-15 0.0215404163180413" rpy="0 0 0" />
      <mass value="0.0273093985570947" />
      <inertia ixx="8.51629628283022E-06" ixy="2.58174336207405E-19" ixz="3.83829504344079E-07"
        iyy="6.9133328065108E-06" iyz="-7.58589926143789E-19" izz="2.25006832221981E-06" />
    </inertial>
    <visual>
      <origin xyz="0 0 0" rpy="0 0 0" />
      <geometry>
        <mesh filename="package://robotiq_arg85_description/meshes/outer_finger_fine.STL" />
      </geometry>
      <material name="Dark2">
        <color
          rgba="0.2 0.2 0.2 1" />
      </material>
    </visual>
    <collision>
      <origin xyz="0 0 0" rpy="0 0 0" />
      <geometry>
        <mesh filename="package://robotiq_arg85_description/meshes/outer_finger_coarse.STL" />
      </geometry>
    </collision>
  </link>
  <joint name="left_outer_finger_joint" type="fixed">
    <origin xyz="0.0316910442266543 0 -0.00183396375724605" rpy="0 0 0" />
    <parent link="left_outer_knuckle" />
    <child link="left_outer_finger" />
    <axis xyz="0 -1 0" />
  </joint>
  <link name="left_inner_knuckle">
    <inertial>
      <origin xyz="0.017097546626628 -3.93808524389535E-10 0.0224918438201868" rpy="0 0 0" />
      <mass value="0.0110930853895903" />
      <inertia ixx="4.23392770691541E-06" ixy="5.748978936968E-15" ixz="1.78855677119788E-06"
        iyy="3.96548790524392E-06" iyz="1.05464666369669E-14" izz="3.24068002883007E-06" />
    </inertial>
    <visual>
      <origin xyz="0 0 0" rpy="0 0 0" />
      <geometry>
        <mesh filename="package://robotiq_arg85_description/meshes/inner_knuckle_fine.STL" />
      </geometry>
      <material name="Dark3">
        <color rgba="0.3 0.3 0.3 1" />
      </material>
    </visual>
    <collision>
      <origin xyz="0 0 0" rpy="0 0 0" />
      <geometry>
        <mesh filename="package://robotiq_arg85_description/meshes/inner_knuckle_coarse.STL" />
      </geometry>
    </collision>
  </link>
  <joint name="left_inner_knuckle_joint" type="revolute">
    <origin xyz="0.0127000000001501 0 0.0693074999999639" rpy="-1.57 0 0" />
    <parent link="robotiq_85_base_link" />
    <child link="left_inner_knuckle" />
    <axis xyz="0 0 -1" />
    <limit lower="0" upper="0.8757" velocity="2.0" effort="1000" />
    <mimic  joint="finger_joint" multiplier="1" offset="0" />
  </joint>
  <link name="left_inner_finger">
    <inertial>
      <origin xyz="0.0060275613594574 -6.29183141465421E-15 0.00669925693133241" rpy="0 0 0" />
      <mass value="0.00724255346165745" />
      <inertia ixx="1.47824274053603E-06" ixy="-3.94884463570303E-19" ixz="-3.45268847648622E-07"
        iyy="1.70064480838395E-06" iyz="3.5059838910097E-19" izz="4.77151336838364E-07" />
    </inertial>
    <visual>
      <origin xyz="0 0 0" rpy="0 0 0" />
      <geometry>
        <mesh filename="package://robotiq_arg85_description/meshes/inner_finger_fine.STL" />
      </geometry>
      <material name="Light09">
        <color rgba="0.9 0.9 0.9 1" />
      </material>
    </visual>
    <collision>
      <origin xyz="0 0 0" rpy="0 0 0" />
      <geometry>
        <mesh filename="package://robotiq_arg85_description/meshes/inner_finger_coarse.STL" />
      </geometry>
    </collision>
  </link>
  <joint name="left_inner_finger_joint" type="revolute">
    <origin xyz="0.034585310861294 -0.0454970193817975 0" rpy="0 0 0" />
    <parent link="left_inner_knuckle" />
    <child link="left_inner_finger" />
    <axis xyz="0 0 1" />
    <limit lower="0" upper="0.8757" velocity="2.0" effort="1000" />
    <mimic  joint="finger_joint" multiplier="-1" offset="0" />
  </joint>
  <link name="right_inner_knuckle">
    <inertial>
      <origin xyz="0.0168606186773776 3.93808471820465E-10 0.0226699950793434" rpy="0 0 0" />
      <mass value="0.0110930853895903" />
      <inertia ixx="4.27134775939882E-06" ixy="-8.53568456728898E-15" ixz="1.77774229944246E-06"
        iyy="3.96548790524392E-06" iyz="-8.45108024914164E-15" izz="3.20325997634666E-06" />
    </inertial>
    <visual>
      <origin xyz="0 0 0" rpy="0 0 0" />
      <geometry>
        <mesh filename="package://robotiq_arg85_description/meshes/inner_knuckle_fine.STL" />
      </geometry>
      <material name="Dark4">
        <color rgba="0.4 0.4 0.4 1" />
      </material>
    </visual>
    <collision>
      <origin xyz="0 0 0" rpy="0 0 0" />
      <geometry>
        <mesh filename="package://robotiq_arg85_description/meshes/inner_knuckle_coarse.STL" />
      </geometry>
    </collision>
  </link>
  <joint name="right_inner_knuckle_joint" type="revolute">
    <origin xyz="-0.0126999999998499 0 0.0693075000000361" rpy="-1.57 0 3.14159265358979" />
    <parent link="robotiq_85_base_link" />
    <child link="right_inner_knuckle" />
    <axis xyz="0 0 -1" />
    <limit lower="0" upper="0.8757" velocity="2.0" effort="1000" />
    <mimic  joint="finger_joint" multiplier="-1" offset="0" />
  </joint>
  <link name="right_inner_finger">
    <inertial>
      <origin xyz="0.00602756228812038 -6.47284509480176E-15 0.00669925609578108" rpy="0 0 0" />
      <mass value="0.00724255346165744" />
      <inertia ixx="1.47824283625957E-06" ixy="-3.95952064019123E-19" ixz="-3.45268708875543E-07"
        iyy="1.70064480838394E-06" iyz="3.55286507960029E-19" izz="4.77151241114822E-07" />
    </inertial>
    <visual>
      <origin xyz="0 0 0" rpy="0 0 0" />
      <geometry>
        <mesh filename="package://robotiq_arg85_description/meshes/inner_finger_fine.STL" />
      </geometry>
      <material name="Light">
        <color rgba="0.792156862745098 0.819607843137255 0.933333333333333 1" />
      </material>
    </visual>
    <collision>
      <origin xyz="0 0 0" rpy="0 0 0" />
      <geometry>
        <mesh filename="package://robotiq_arg85_description/meshes/inner_finger_coarse.STL" />
      </geometry>
    </collision>
  </link>
  <joint name="right_inner_finger_joint" type="revolute">
    <origin xyz="0.0341060475457406 -0.0458573878541688 0 " rpy="0 0 0" />
    <parent link="right_inner_knuckle" />
    <child link="right_inner_finger" />
    <axis xyz="0 0 1" />
    <limit lower="0" upper="0.8757" velocity="2.0" effort="1000" />
    <mimic  joint="finger_joint" multiplier="1" offset="0" />
  </joint>
  <link name="right_outer_knuckle">
    <inertial>
      <origin xyz="0.0178097074051638 3.60493211424024E-11 0.00233123458346721" rpy="0 0 0" />
      <mass value="0.00684838849401352" />
      <inertia ixx="2.70004361573169E-07" ixy="1.59579467624491E-15" ixz="1.56396493788199E-07"
        iyy="1.38892332558312E-06" iyz="2.82357800318817E-15" izz="1.26286103637978E-06" />
    </inertial>
    <visual>
      <origin xyz="0 0 0" rpy="0 0 0" />
      <geometry>
        <mesh filename="package://robotiq_arg85_description/meshes/outer_knuckle_fine.STL" />
      </geometry>
      <material name="Light">
        <color
          rgba="0.792156862745098 0.819607843137255 0.933333333333333 1" />
      </material>
    </visual>
    <collision>
      <origin xyz="0 0 0" rpy="0 0 0" />
      <geometry>
        <mesh filename="package://robotiq_arg85_description/meshes/outer_knuckle_coarse.STL" />
      </geometry>
    </collision>
  </link>
  <joint name="right_outer_knuckle_joint" type="revolute">
    <origin xyz="-0.0306011444258893 0 0.0627920162695395" rpy="-1.57 0 3.14159265358979" />
    <parent link="robotiq_85_base_link" />
    <child link="right_outer_knuckle" />
    <axis xyz="0 0 -1" />
    <limit lower="0" upper="0.8757" velocity="2.0" effort="1000" />
    <mimic  joint="finger_joint" multiplier="-1" offset="0" />
  </joint>
  <link name="right_outer_finger">
    <inertial>
      <origin xyz="0.00108844269639009 -2.611488350845E-15 0.0215530225245502" rpy="0 0 0" />
      <mass value="0.0273093985570947" />
      <inertia ixx="8.52366028592721E-06" ixy="3.41683380899422E-19" ixz="3.18003675694284E-07"
        iyy="6.91333280651081E-06" iyz="7.37726682706417E-19" izz="2.24270431912283E-06" />
    </inertial>
    <visual>
      <origin xyz="0 0 0" rpy="0 0 0" />
      <geometry>
        <mesh filename="package://robotiq_arg85_description/meshes/outer_finger_fine.STL" />
      </geometry>
      <material name="Dark2">
        <color rgba="0.2 0.2 0.2 1" />
      </material>
    </visual>
    <collision>
      <origin xyz="0 0 0" rpy="0 0 0" />
      <geometry>
        <mesh filename="package://robotiq_arg85_description/meshes/outer_finger_coarse.STL" />
      </geometry>
    </collision>
  </link>
  <joint name="right_outer_finger_joint" type="fixed">
    <origin xyz="0.0317095909367246 0 -0.0016013564954687" rpy="0 0 0" />
    <parent link="right_outer_knuckle" />
    <child link="right_outer_finger" />
    <axis xyz="0 1 0" />
  </joint>
</robot>
